Workbook

Sheet Resultados_Construtivas
B1: Vizinho mais próximo d-relaxado | E1: Inserção d-relaxada | H1: GILS-RVND
A2: Instance | B2: Solution | C2: Dif(%) | D2: Time | E2: Solution | F2: Dif(%) | G2: Time | H2: Best | I2: Gapav | J2: Timeav | K2: Solav
A3: berlin52-C-1-0-a | B3: 8980 | C3: =((B3 -H3)/B3 * 100) -> 16.013363 | D3: 0.0003052 | E3: 8307 | F3: =((E3 - H3)/H3 * 100) -> 10.143198 | G3: 0.0014879 | H3: 7542 | I3: 0 | J3: 7.86
A4: berlin52-C-3-0-a | B4: 9401 | C4: =((B4 -H4)/B4 * 100) -> 13.370918 | D4: 0.00028749998 | E4: 8642 | F4: =((E4 - H4)/H4 * 100) -> 6.1149312 | G4: 0.0012291 | H4: 8144 | I4: 0 | J4: 7.59
A5: berlin52-C-3-0-b | B5: 8699 | C5: =((B5 -H5)/B5 * 100) -> 7.8514772 | D5: 0.00027889991 | E5: 8868 | F5: =((E5 - H5)/H5 * 100) -> 10.628743 | G5: 0.00075940001 | H5: 8016 | I5: 0 | J5: 5.96
A6: berlin52-C-3-0-c | B6: 11089 | C6: =((B6 -H6)/B6 * 100) -> 18.071963 | D6: 0.00028600008 | E6: 10418 | F6: =((E6 - H6)/H6 * 100) -> 14.672537 | G6: 0.00095620001 | H6: 9085 | I6: 0.07 | J6: 6.77
A7: berlin52-C-3-1-a | B7: 10339 | C7: =((B7 -H7)/B7 * 100) -> 23.087339 | D7: 0.00031130004 | E7: 8642 | F7: =((E7 - H7)/H7 * 100) -> 8.6770624 | G7: 0.0012819 | H7: 7952 | I7: 0 | J7: 8.61
A8: berlin52-C-3-1-b | B8: 10061 | C8: =((B8 -H8)/B8 * 100) -> 24.500547 | D8: 0.00029900006 | E8: 8602 | F8: =((E8 - H8)/H8 * 100) -> 13.243813 | G8: 0.0010756 | H8: 7596 | I8: 0 | J8: 7.24
A9: berlin52-C-3-1-c | B9: 8980 | C9: =((B9 -H9)/B9 * 100) -> 11.091314 | D9: 0.00031419995 | E9: 9385 | F9: =((E9 - H9)/H9 * 100) -> 17.547595 | G9: 0.0013822 | H9: 7984 | I9: 0 | J9: 8.2
A10: berlin52-C-5-0-a | B10: 11717 | C10: =((B10 -H10)/B10 * 100) -> 19.518648 | D10: 0.0003187001 | E10: 10619 | F10: =((E10 - H10)/H10 * 100) -> 12.608696 | G10: 0.00085340001 | H10: 9430 | I10: 0 | J10: 5.85
A11: berlin52-C-5-0-b | B11: 10669 | C11: =((B11 -H11)/B11 * 100) -> 18.745899 | D11: 0.00027660001 | E11: 9181 | F11: =((E11 - H11)/H11 * 100) -> 5.9061022 | G11: 0.00084379999 | H11: 8669 | I11: 0 | J11: 5.13
A12: berlin52-C-5-0-c | B12: 10455 | C12: =((B12 -H12)/B12 * 100) -> 7.6901004 | D12: 0.0002754 | E12: 9819 | F12: =((E12 - H12)/H12 * 100) -> 1.7407523 | G12: 0.00072649999 | H12: 9651 | I12: 0 | J12: 5.69
A13: berlin52-C-5-1-a | B13: 11497 | C13: =((B13 -H13)/B13 * 100) -> 23.362616 | D13: 0.00029240001 | E13: 10729 | F13: =((E13 - H13)/H13 * 100) -> 21.768244 | G13: 0.0009867 | H13: 8811 | I13: 0.1 | J13: 7.15
A14: berlin52-C-5-1-b | B14: 9432 | C14: =((B14 -H14)/B14 * 100) -> 15.733673 | D14: 0.00029520004 | E14: 9060 | F14: =((E14 - H14)/H14 * 100) -> 13.990941 | G14: 0.0011491 | H14: 7948 | I14: 0 | J14: 6.51
... A34: berlin52-R-5-3-c | B34: 9715 | C34: =((B34 -H34)/B34 * 100) -> 15.347401 | D34: 0.00033339998 | E34: 9788 | F34: =((E34 - H34)/H34 * 100) -> 19.01751 | G34: 0.001097 | H34: 8224 | I34: 0 | J34: 7.36
A35: kroA100-C-1-0-a | B35: 27807 | C35: =((B35 -H35)/B35 * 100) -> 23.465314 | D35: 0.0010217001 | E35: 23186 | F35: =((E35 - H35)/H35 * 100) -> 8.9465276 | G35: 0.0081904 | H35: 21282 | I35: 0.26 | J35: 84.88 | K35: 21338.6
A36: kroA100-C-3-0-a | B36: 30288 | C36: =((B36 -H36)/B36 * 100) -> 20.598917 | D36: 0.00099929993 | E36: 26147 | F36: =((E36 - H36)/H36 * 100) -> 8.7238555 | G36: 0.0045935 | H36: 24049 | I36: 0 | J36: 67.93 | K36: 24049
A37: kroA100-C-3-1-a | B37: 30070 | C37: =((B37 -H37)/B37 * 100) -> 23.282341 | D37: 0.0010494 | E37: 25166 | F37: =((E37 - H37)/H37 * 100) -> 9.0901209 | G37: 0.006848 | H37: 23069 | I37: 1.48 | J37: 80.07 | K37: 23416.7
A38: kroA100-C-5-0-a | B38: 30969 | C38: =((B38 -H38)/B38 * 100) -> 20.097517 | D38: 0.00090770004 | E38: 26474 | F38: =((E38 - H38)/H38 * 100) -> 6.9872702 | G38: 0.0031891 | H38: 24745 | I38: 0 | J38: 58.51 | K38: 24745
A39: kroA100-C-5-1-a | B39: 28689 | C39: =((B39 -H39)/B39 * 100) -> 21.262505 | D39: 0.00094489998 | E39: 25970 | F39: =((E39 - H39)/H39 * 100) -> 14.967462 | G39: 0.0047863 | H39: 22589 | I39: 0.01 | J39: 84.44 | K39: 22591.8
A40: kroA100-C-5-3-a | B40: 27445 | C40: =((B40 -H40)/B40 * 100) -> 21.869193 | D40: 0.0010041 | E40: 31083 | F40: =((E40 - H40)/H40 * 100) -> 44.956396 | G40: 0.005806 | H40: 21443 | I40: 0 | J40: 82.5 | K40: 21443
A41: kroA100-R-1-0-a | B41: 27807 | C41: =((B41 -H41)/B41 * 100) -> 23.465314 | D41: 0.0010149 | E41: 23186 | F41: =((E41 - H41)/H41 * 100) -> 8.9465276 | G41: 0.0086055 | H41: 21282 | I41: 0.39 | J41: 95.23 | K41: 21365.5
A42: kroA100-R-3-0-a | B42: 44136 | C42: =((B42 -H42)/B42 * 100) -> 12.058184 | D42: 0.00096809992 | E42: 43411 | F42: =((E42 - H42)/H42 * 100) -> 11.843665 | G42: 0.0037043 | H42: 38814 | I42: 0.16 | J42: 73.43 | K42: 38877.5
A43: kroA100-R-3-1-a | B43: 36649 | C43: =((B43 -H43)/B43 * 100) -> 20.150618 | D43: 0.0010399 | E43: 33156 | F43: =((E43 - H43)/H43 * 100) -> 13.299617 | G43: 0.0047723 | H43: 29264 | I43: 1.05 | J43: 92.64 | K43: 29578.2
A44: kroA100-R-5-0-a | B44: 55382 | C44: =((B44 -H44)/B44 * 100) -> 9.3712759 | D44: 0.00093059998 | E44: 54878 | F44: =((E44 - H44)/H44 * 100) -> 9.3361492 | G44: 0.0025873 | H44: 50192 | I44: 0.43 | J44: 63.04 | K44: 50411
A45: kroA100-R-5-1-a | B45: 44855 | C45: =((B45 -H45)/B45 * 100) -> 20.082488 | D45: 0.00093560002 | E45: 46080 | F45: =((E45 - H45)/H45 * 100) -> 28.546322 | G45: 0.0032116 | H45: 35847 | I45: 1.32 | J45: 72.97 | K45: 36328.4
A46: kroA100-R-5-3-a | B46: 33384 | C46: =((B46 -H46)/B46 * 100) -> 24.005512 | D46: 0.0010014001 | E46: 41047 | F46: =((E46 - H46)/H46 * 100) -> 61.793457 | G46: 0.006266 | H46: 25370 | I46: 0.87 | J46: 90.97 | K46: 25594.9
... A118: kroE100-R-5-3-a | B118: 34112 | C118: =((B118 -H118)/B118 * 100) -> 20.098499 | D118: 0.0010103 | E118: 32257 | F118: =((E118 - H118)/H118 * 100) -> 18.348254 | G118: 0.0056998 | H118: 27256 | I118: 0.22 | J118: 109.86 | K118: 27316.3
A119: swiss42-C-1-0-a | B119: 1630 | C119: =((B119 -H119)/B119 * 100) -> 21.90184 | D119: 0.00020689995 | E119: 1404 | F119: =((E119 - H119)/H119 * 100) -> 10.290652 | G119: 0.00096139999 | H119: 1273 | I119: 0 | J119: 4.65
A120: swiss42-C-3-0-a | B120: 1483 | C120: =((B120 -H120)/B120 * 100) -> 9.1706001 | D120: 0.00019060005 | E120: 1470 | F120: =((E120 - H120)/H120 * 100) -> 9.1314031 | G120: 0.00045180001 | H120: 1347 | I120: 0 | J120: 3.56
A121: swiss42-C-3-0-b | B121: 1908 | C121: =((B121 -H121)/B121 * 100) -> 21.121593 | D121: 0.00021309999 | E121: 1609 | F121: =((E121 - H121)/H121 * 100) -> 6.910299 | G121: 0.0005291 | H121: 1505 | I121: 0 | J121: 3.67
A122: swiss42-C-3-0-c | B122: 1779 | C122: =((B122 -H122)/B122 * 100) -> 17.537943 | D122: 0.00018650002 | E122: 1632 | F122: =((E122 - H122)/H122 * 100) -> 11.247444 | G122: 0.0005178 | H122: 1467 | I122: 0 | J122: 3.26
A123: swiss42-C-3-1-a | B123: 1485 | C123: =((B123 -H123)/B123 * 100) -> 12.390572 | D123: 0.00067189999 | E123: 1441 | F123: =((E123 - H123)/H123 * 100) -> 10.760953 | G123: 0.0006023 | H123: 1301 | I123: 0.14 | J123: 4.31
A124: swiss42-C-3-1-b | B124: 1777 | C124: =((B124 -H124)/B124 * 100) -> 24.366911 | D124: 0.000199 | E124: 1602 | F124: =((E124 - H124)/H124 * 100) -> 19.196429 | G124: 0.0006615 | H124: 1344 | I124: 0 | J124: 4.3
A125: swiss42-C-3-1-c | B125: 1725 | C125: =((B125 -H125)/B125 * 100) -> 21.333333 | D125: 0.0001988 | E125: 1492 | F125: =((E125 - H125)/H125 * 100) -> 9.9484156 | G125: 0.00056829999 | H125: 1357 | I125: 0 | J125: 4.26
A126: swiss42-C-5-0-a | B126: 1886 | C126: =((B126 -H126)/B126 * 100) -> 17.232238 | D126: 0.0001836 | E126: 1583 | F126: =((E126 - H126)/H126 * 100) -> 1.409353 | G126: 0.0004106 | H126: 1561 | I126: 0 | J126: 3.01
A127: swiss42-C-5-0-b | B127: 1872 | C127: =((B127 -H127)/B127 * 100) -> 17.735043 | D127: 0.0001832 | E127: 1617 | F127: =((E127 - H127)/H127 * 100) -> 5 | G127: 0.00039890001 | H127: 1540 | I127: 0 | J127: 2.89
A128: swiss42-C-5-0-c | B128: 1841 | C128: =((B128 -H128)/B128 * 100) -> 16.784356 | D128: 0.00018710003 | E128: 1693 | F128: =((E128 - H128)/H128 * 100) -> 10.509138 | G128: 0.0004017 | H128: 1532 | I128: 0 | J128: 3.03
A129: swiss42-C-5-1-a | B129: 1733 | C129: =((B129 -H129)/B129 * 100) -> 17.253318 | D129: 0.00018999993 | E129: 1658 | F129: =((E129 - H129)/H129 * 100) -> 15.620642 | G129: 0.0005365 | H129: 1434 | I129: 0 | J129: 4.11
A130: swiss42-C-5-1-b | B130: 1815 | C130: =((B130 -H130)/B130 * 100) -> 19.063361 | D130: 0.00019399996 | E130: 1633 | F130: =((E130 - H130)/H130 * 100) -> 11.164057 | G130: 0.00052099999 | H130: 1469 | I130: 0 | J130: 4.3
...

Sheet Média das dif
G2: Média das Dif(%)
F3: Instâncias | G3: Vizinho mais próximo d-relaxado | H3: Inserção d-relaxada
F4: berlin52 | G4: =AVERAGE(Resultados_Construtivas!C3:C34) -> 17.5835 | H4: =AVERAGE(Resultados_Construtivas!F3:F34) -> 17.084623
F5: kroA100 | G5: =AVERAGE(Resultados_Construtivas!C35:C46) -> 19.975765 | H5: =AVERAGE(Resultados_Construtivas!F35:F46) -> 18.953114
F6: kroA200 | G6: =AVERAGE(Resultados_Construtivas!C47:C58) -> 19.923058 | H6: =AVERAGE(Resultados_Construtivas!F47:F58) -> 15.092047
F7: kroB100 | G7: =AVERAGE(Resultados_Construtivas!C59:C70) -> 21.156083 | H7: =AVERAGE(Resultados_Construtivas!F59:F70) -> 16.500923
F8: kroB200 | G8: =AVERAGE(Resultados_Construtivas!C71:C82) -> 19.725869 | H8: =AVERAGE(Resultados_Construtivas!F71:F82) -> 13.373788
F9: kroC100 | G9: =AVERAGE(Resultados_Construtivas!C83:C94) -> 19.621836 | H9: =AVERAGE(Resultados_Construtivas!F83:F94) -> 18.762096
F10: kroD100 | G10: =AVERAGE(Resultados_Construtivas!C95:C106) -> 20.504839 | H10: =AVERAGE(Resultados_Construtivas!F95:F106) -> 15.986971
F11: kroE100 | G11: =AVERAGE(Resultados_Construtivas!C107:C118) -> 17.630521 | H11: =AVERAGE(Resultados_Construtivas!F107:F118) -> 16.268028
F12: swiss42 | G12: =AVERAGE(Resultados_Construtivas!C119:C150) -> 16.803949 | H12: =AVERAGE(Resultados_Construtivas!F119:F150) -> 15.775038
