Workbook

Sheet Resultados_VND
B1: Vizinho mais próximo d-relaxado VND | E1: Inserção d-relaxada VND | H1: GILS-RVND
A2: Instance | B2: Solution | C2: Dif(%) | D2: Time | E2: Solution | F2: Dif(%) | G2: Time | H2: Best | I2: Gapav | J2: Timeav | K2: Solav
A3: berlin52-C-1-0-a | B3: 8321 | C3: =((B3 -H3)/B3 * 100) -> 9.3618555 | D3: 0.6531853 | E3: 7862 | F3: =((E3 -H3)/ E3 * 100) -> 4.0702111 | G3: 1.0455631 | H3: 7542 | I3: 0 | J3: 7.86
A4: berlin52-C-3-0-a | B4: 8442 | C4: =((B4 -H4)/B4 * 100) -> 3.5299692 | D4: 0.3512482 | E4: 8287 | F4: =((E4 -H4)/ E4 * 100) -> 1.7255943 | G4: 0.3478273 | H4: 8144 | I4: 0 | J4: 7.59
A5: berlin52-C-3-0-b | B5: 8038 | C5: =((B5 -H5)/B5 * 100) -> 0.27369993 | D5: 0.2897145 | E5: 8559 | F5: =((E5 -H5)/ E5 * 100) -> 6.3441991 | G5: 0.2515617 | H5: 8016 | I5: 0 | J5: 5.96
A6: berlin52-C-3-0-c | B6: 10211 | C6: =((B6 -H6)/B6 * 100) -> 11.027323 | D6: 0.5389606 | E6: 9669 | F6: =((E6 -H6)/ E6 * 100) -> 6.0399214 | G6: 0.7841647 | H6: 9085 | I6: 0.07 | J6: 6.77
A7: berlin52-C-3-1-a | B7: 8702 | C7: =((B7 -H7)/B7 * 100) -> 8.6187083 | D7: 1.1729763 | E7: 8287 | F7: =((E7 -H7)/ E7 * 100) -> 4.0424762 | G7: 0.4094881 | H7: 7952 | I7: 0 | J7: 8.61
A8: berlin52-C-3-1-b | B8: 9368 | C8: =((B8 -H8)/B8 * 100) -> 18.915457 | D8: 0.4638746 | E8: 7862 | F8: =((E8 -H8)/ E8 * 100) -> 3.383363 | G8: 0.8432494 | H8: 7596 | I8: 0 | J8: 7.24
A9: berlin52-C-3-1-c | B9: 8550 | C9: =((B9 -H9)/B9 * 100) -> 6.619883 | D9: 0.6481683 | E9: 8310 | F9: =((E9 -H9)/ E9 * 100) -> 3.9229844 | G9: 0.7124594 | H9: 7984 | I9: 0 | J9: 8.2
A10: berlin52-C-5-0-a | B10: 9704 | C10: =((B10 -H10)/B10 * 100) -> 2.8235779 | D10: 0.3263692 | E10: 9934 | F10: =((E10 -H10)/ E10 * 100) -> 5.073485 | G10: 0.2852315 | H10: 9430 | I10: 0 | J10: 5.85
A11: berlin52-C-5-0-b | B11: 9206 | C11: =((B11 -H11)/B11 * 100) -> 5.8331523 | D11: 0.9611087 | E11: 9060 | F11: =((E11 -H11)/ E11 * 100) -> 4.3156733 | G11: 0.1871247 | H11: 8669 | I11: 0 | J11: 5.13
A12: berlin52-C-5-0-c | B12: 9949 | C12: =((B12 -H12)/B12 * 100) -> 2.9952759 | D12: 0.3259897 | E12: 9764 | F12: =((E12 -H12)/ E12 * 100) -> 1.1573126 | G12: 0.3257135 | H12: 9651 | I12: 0 | J12: 5.69
A13: berlin52-C-5-1-a | B13: 10106 | C13: =((B13 -H13)/B13 * 100) -> 12.81417 | D13: 0.563862 | E13: 9524 | F13: =((E13 -H13)/ E13 * 100) -> 7.4863503 | G13: 0.9465927 | H13: 8811 | I13: 0.1 | J13: 7.15
A14: berlin52-C-5-1-b | B14: 8258 | C14: =((B14 -H14)/B14 * 100) -> 3.7539356 | D14: 0.8167766 | E14: 8472 | F14: =((E14 -H14)/ E14 * 100) -> 6.1850803 | G14: 0.2997899 | H14: 7948 | I14: 0 | J14: 6.51
... A34: berlin52-R-5-3-c | B34: 8904 | C34: =((B34 -H34)/B34 * 100) -> 7.6370171 | D34: 0.4325333 | E34: 9337 | F34: =((E34 -H34)/ E34 * 100) -> 11.920317 | G34: 0.4893986 | H34: 8224 | I34: 0 | J34: 7.36
A35: kroA100-C-1-0-a | B35: 24474 | C35: =((B35 -H35)/B35 * 100) -> 13.042412 | D35: 3.6334938 | E35: 22424 | F35: =((E35 -H35)/ E35 * 100) -> 5.0927578 | G35: 3.2086128 | H35: 21282 | I35: 0.26 | J35: 84.88 | K35: 21338.6
A36: kroA100-C-3-0-a | B36: 27246 | C36: =((B36 -H36)/B36 * 100) -> 11.733832 | D36: 6.1859015 | E36: 25105 | F36: =((E36 -H36)/ E36 * 100) -> 4.2063334 | G36: 2.8914676 | H36: 24049 | I36: 0 | J36: 67.93 | K36: 24049
A37: kroA100-C-3-1-a | B37: 25177 | C37: =((B37 -H37)/B37 * 100) -> 8.3727211 | D37: 4.3589774 | E37: 24591 | F37: =((E37 -H37)/ E37 * 100) -> 6.1892562 | G37: 2.4766558 | H37: 23069 | I37: 1.48 | J37: 80.07 | K37: 23416.7
A38: kroA100-C-5-0-a | B38: 25179 | C38: =((B38 -H38)/B38 * 100) -> 1.7236586 | D38: 3.5230916 | E38: 25367 | F38: =((E38 -H38)/ E38 * 100) -> 2.4520046 | G38: 1.3666774 | H38: 24745 | I38: 0 | J38: 58.51 | K38: 24745
A39: kroA100-C-5-1-a | B39: 26018 | C39: =((B39 -H39)/B39 * 100) -> 13.179337 | D39: 3.2063219 | E39: 24432 | F39: =((E39 -H39)/ E39 * 100) -> 7.5433857 | G39: 3.144739 | H39: 22589 | I39: 0.01 | J39: 84.44 | K39: 22591.8
A40: kroA100-C-5-3-a | B40: 24624 | C40: =((B40 -H40)/B40 * 100) -> 12.918291 | D40: 4.8159017 | E40: 24723 | F40: =((E40 -H40)/ E40 * 100) -> 13.266998 | G40: 4.333942 | H40: 21443 | I40: 0 | J40: 82.5 | K40: 21443
A41: kroA100-R-1-0-a | B41: 24474 | C41: =((B41 -H41)/B41 * 100) -> 13.042412 | D41: 3.6269304 | E41: 22424 | F41: =((E41 -H41)/ E41 * 100) -> 5.0927578 | G41: 3.1707431 | H41: 21282 | I41: 0.39 | J41: 95.23 | K41: 21365.5
A42: kroA100-R-3-0-a | B42: 42058 | C42: =((B42 -H42)/B42 * 100) -> 7.713158 | D42: 2.6140996 | E42: 41559 | F42: =((E42 -H42)/ E42 * 100) -> 6.6050675 | G42: 1.8484774 | H42: 38814 | I42: 0.16 | J42: 73.43 | K42: 38877.5
A43: kroA100-R-3-1-a | B43: 33097 | C43: =((B43 -H43)/B43 * 100) -> 11.58111 | D43: 4.7663798 | E43: 31316 | F43: =((E43 -H43)/ E43 * 100) -> 6.552561 | G43: 3.964558 | H43: 29264 | I43: 1.05 | J43: 92.64 | K43: 29578.2
A44: kroA100-R-5-0-a | B44: 52633 | C44: =((B44 -H44)/B44 * 100) -> 4.6377748 | D44: 2.8334378 | E44: 52956 | F44: =((E44 -H44)/ E44 * 100) -> 5.2194274 | G44: 2.3191372 | H44: 50192 | I44: 0.43 | J44: 63.04 | K44: 50411
A45: kroA100-R-5-1-a | B45: 37085 | C45: =((B45 -H45)/B45 * 100) -> 3.3382769 | D45: 5.8231239 | E45: 41940 | F45: =((E45 -H45)/ E45 * 100) -> 14.527897 | G45: 2.5848927 | H45: 35847 | I45: 1.32 | J45: 72.97 | K45: 36328.4
A46: kroA100-R-5-3-a | B46: 29547 | C46: =((B46 -H46)/B46 * 100) -> 14.136799 | D46: 4.7171739 | E46: 29558 | F46: =((E46 -H46)/ E46 * 100) -> 14.168753 | G46: 5.4733392 | H46: 25370 | I46: 0.87 | J46: 90.97 | K46: 25594.9
... A118: kroE100-R-5-3-a | B118: 28597 | C118: =((B118 -H118)/B118 * 100) -> 4.6893031 | D118: 6.0994768 | E118: 28838 | F118: =((E118 -H118)/ E118 * 100) -> 5.4858173 | G118: 3.6357311 | H118: 27256 | I118: 0.22 | J118: 109.86 | K118: 27316.3
A119: swiss42-C-1-0-a | B119: 1444 | C119: =((B119 -H119)/B119 * 100) -> 11.842105 | D119: 0.4459614 | E119: 1315 | F119: =((E119 -H119)/ E119 * 100) -> 3.1939163 | G119: 0.239596 | H119: 1273 | I119: 0 | J119: 4.65
A120: swiss42-C-3-0-a | B120: 1347 | C120: =((B120 -H120)/B120 * 100) -> 0 | D120: 0.1934177 | E120: 1376 | F120: =((E120 -H120)/ E120 * 100) -> 2.1075581 | G120: 0.2436272 | H120: 1347 | I120: 0 | J120: 3.56
A121: swiss42-C-3-0-b | B121: 1556 | C121: =((B121 -H121)/B121 * 100) -> 3.277635 | D121: 0.2185827 | E121: 1505 | F121: =((E121 -H121)/ E121 * 100) -> 0 | G121: 0.2256532 | H121: 1505 | I121: 0 | J121: 3.67
A122: swiss42-C-3-0-c | B122: 1512 | C122: =((B122 -H122)/B122 * 100) -> 2.9761905 | D122: 0.2850277 | E122: 1501 | F122: =((E122 -H122)/ E122 * 100) -> 2.2651566 | G122: 0.1755474 | H122: 1467 | I122: 0 | J122: 3.26
A123: swiss42-C-3-1-a | B123: 1301 | C123: =((B123 -H123)/B123 * 100) -> 0 | D123: 0.3165477 | E123: 1310 | F123: =((E123 -H123)/ E123 * 100) -> 0.6870229 | G123: 0.2005326 | H123: 1301 | I123: 0.14 | J123: 4.31
A124: swiss42-C-3-1-b | B124: 1410 | C124: =((B124 -H124)/B124 * 100) -> 4.6808511 | D124: 0.2850529 | E124: 1417 | F124: =((E124 -H124)/ E124 * 100) -> 5.151729 | G124: 0.2794961 | H124: 1344 | I124: 0 | J124: 4.3
A125: swiss42-C-3-1-c | B125: 1469 | C125: =((B125 -H125)/B125 * 100) -> 7.6242342 | D125: 0.2789212 | E125: 1441 | F125: =((E125 -H125)/ E125 * 100) -> 5.8292852 | G125: 0.2123966 | H125: 1357 | I125: 0 | J125: 4.26
A126: swiss42-C-5-0-a | B126: 1600 | C126: =((B126 -H126)/B126 * 100) -> 2.4375 | D126: 0.2634245 | E126: 1574 | F126: =((E126 -H126)/ E126 * 100) -> 0.82592122 | G126: 0.0954523 | H126: 1561 | I126: 0 | J126: 3.01
A127: swiss42-C-5-0-b | B127: 1603 | C127: =((B127 -H127)/B127 * 100) -> 3.930131 | D127: 0.1825069 | E127: 1540 | F127: =((E127 -H127)/ E127 * 100) -> 0 | G127: 0.1366365 | H127: 1540 | I127: 0 | J127: 2.89
A128: swiss42-C-5-0-c | B128: 1546 | C128: =((B128 -H128)/B128 * 100) -> 0.90556274 | D128: 0.1347585 | E128: 1669 | F128: =((E128 -H128)/ E128 * 100) -> 8.2085081 | G128: 0.0937571 | H128: 1532 | I128: 0 | J128: 3.03
A129: swiss42-C-5-1-a | B129: 1501 | C129: =((B129 -H129)/B129 * 100) -> 4.4636909 | D129: 0.2554783 | E129: 1479 | F129: =((E129 -H129)/ E129 * 100) -> 3.0425963 | G129: 0.2189121 | H129: 1434 | I129: 0 | J129: 4.11
A130: swiss42-C-5-1-b | B130: 1554 | C130: =((B130 -H130)/B130 * 100) -> 5.4697555 | D130: 0.1424599 | E130: 1532 | F130: =((E130 -H130)/ E130 * 100) -> 4.1122715 | G130: 0.1457193 | H130: 1469 | I130: 0 | J130: 4.3
...

Sheet Média das dif VND
I6: Média das Dif(%)
H7: Instâncias | I7: Vizinho mais próximo d-relaxado com VND | J7: Inserção d-relaxada com VND
H8: berlin52 | I8: =AVERAGE(Resultados_VND!C3:C34) -> 7.2434632 | J8: =AVERAGE(Resultados_VND!F3:F34) -> 8.3653867
H9: kroA100 | I9: =AVERAGE(Resultados_VND!C35:C46) -> 9.6183154 | J9: =AVERAGE(Resultados_VND!F35:F46) -> 7.5764333
H10: kroA200 | I10: =AVERAGE(Resultados_VND!C47:C58) -> 8.4384624 | J10: =AVERAGE(Resultados_VND!F47:F58) -> 6.2189506
H11: kroB100 | I11: =AVERAGE(Resultados_VND!C59:C70) -> 8.7390221 | J11: =AVERAGE(Resultados_VND!F59:F70) -> 6.3285526
H12: kroB200 | I12: =AVERAGE(Resultados_VND!C71:C82) -> 8.6414879 | J12: =AVERAGE(Resultados_VND!F71:F82) -> 5.1682478
H13: kroC100 | I13: =AVERAGE(Resultados_VND!C83:C94) -> 9.7459109 | J13: =AVERAGE(Resultados_VND!F83:F94) -> 6.3374193
H14: kroD100 | I14: =AVERAGE(Resultados_VND!C95:C106) -> 9.8867679 | J14: =AVERAGE(Resultados_VND!F95:F106) -> 7.3000415
H15: kroE100 | I15: =AVERAGE(Resultados_VND!C107:C118) -> 8.0299919 | J15: =AVERAGE(Resultados_VND!F107:F118) -> 6.0533166
H16: swiss42 | I16: =AVERAGE(Resultados_VND!C119:C150) -> 5.9605448 | J16: =AVERAGE(Resultados_VND!F119:F150) -> 5.6698952
