Workbook

Sheet Resultados_ILS
B1: Vizinho mais próximo d-relaxada com ILS | E1: Inserção d-relaxada com ILS | H1: GILS-RVND
A2: Instance | B2: Solution | C2: Dif(%) | D2: Time | E2: Solution | F2: Dif(%) | G2: Time | H2: Best | I2: Gapav | J2: Timeav | K2: Solav
A3: berlin52-C-1-0-a | B3: 8321 | C3: =((B3 -H3)/B3 * 100) -> 9.3618555 | D3: 2.4446014 | E3: 7862 | F3: =((E3 -H3)/E3 * 100) -> 4.0702111 | G3: 3.4890073 | H3: 7542 | I3: 0 | J3: 7.86
A4: berlin52-C-3-0-a | B4: 8442 | C4: =((B4 -H4)/B4 * 100) -> 3.5299692 | D4: 1.974475 | E4: 8287 | F4: =((E4 -H4)/E4 * 100) -> 1.7255943 | G4: 1.7293347 | H4: 8144 | I4: 0 | J4: 7.59
A5: berlin52-C-3-0-b | B5: 8016 | C5: =((B5 -H5)/B5 * 100) -> 0 | D5: 1.8023775 | E5: 8559 | F5: =((E5 -H5)/E5 * 100) -> 6.3441991 | G5: 1.7302684 | H5: 8016 | I5: 0 | J5: 5.96
A6: berlin52-C-3-0-c | B6: 9573 | C6: =((B6 -H6)/B6 * 100) -> 5.0976705 | D6: 2.8274881 | E6: 9490 | F6: =((E6 -H6)/E6 * 100) -> 4.2676502 | G6: 2.409947 | H6: 9085 | I6: 0.07 | J6: 6.77
A7: berlin52-C-3-1-a | B7: 8621 | C7: =((B7 -H7)/B7 * 100) -> 7.7601206 | D7: 3.1485338 | E7: 7959 | F7: =((E7 -H7)/E7 * 100) -> 0.087950748 | G7: 2.5222284 | H7: 7952 | I7: 0 | J7: 8.61
A8: berlin52-C-3-1-b | B8: 9307 | C8: =((B8 -H8)/B8 * 100) -> 18.384012 | D8: 2.4384779 | E8: 7862 | F8: =((E8 -H8)/E8 * 100) -> 3.383363 | G8: 2.7521195 | H8: 7596 | I8: 0 | J8: 7.24
A9: berlin52-C-3-1-c | B9: 8463 | C9: =((B9 -H9)/B9 * 100) -> 5.6599315 | D9: 2.6013342 | E9: 7990 | F9: =((E9 -H9)/E9 * 100) -> 0.075093867 | G9: 3.2464252 | H9: 7984 | I9: 0 | J9: 8.2
A10: berlin52-C-5-0-a | B10: 9704 | C10: =((B10 -H10)/B10 * 100) -> 2.8235779 | D10: 1.4998203 | E10: 9934 | F10: =((E10 -H10)/E10 * 100) -> 5.073485 | G10: 1.2962208 | H10: 9430 | I10: 0 | J10: 5.85
A11: berlin52-C-5-0-b | B11: 9170 | C11: =((B11 -H11)/B11 * 100) -> 5.4634678 | D11: 1.9621887 | E11: 8669 | F11: =((E11 -H11)/E11 * 100) -> 0 | G11: 1.3987061 | H11: 8669 | I11: 0 | J11: 5.13
A12: berlin52-C-5-0-c | B12: 9949 | C12: =((B12 -H12)/B12 * 100) -> 2.9952759 | D12: 1.2199451 | E12: 9764 | F12: =((E12 -H12)/E12 * 100) -> 1.1573126 | G12: 1.5386583 | H12: 9651 | I12: 0 | J12: 5.69
A13: berlin52-C-5-1-a | B13: 10092 | C13: =((B13 -H13)/B13 * 100) -> 12.693222 | D13: 1.9876476 | E13: 9521 | F13: =((E13 -H13)/E13 * 100) -> 7.4571999 | G13: 2.6103388 | H13: 8811 | I13: 0.1 | J13: 7.15
A14: berlin52-C-5-1-b | B14: 8258 | C14: =((B14 -H14)/B14 * 100) -> 3.7539356 | D14: 2.5074047 | E14: 8472 | F14: =((E14 -H14)/E14 * 100) -> 6.1850803 | G14: 1.5520493 | H14: 7948 | I14: 0 | J14: 6.51
... A34: berlin52-R-5-3-c | B34: 8904 | C34: =((B34 -H34)/B34 * 100) -> 7.6370171 | D34: 2.3915829 | E34: 9337 | F34: =((E34 -H34)/E34 * 100) -> 11.920317 | G34: 2.4231395 | H34: 8224 | I34: 0 | J34: 7.36
A35: kroA100-C-1-0-a | B35: 24474 | C35: =((B35 -H35)/B35 * 100) -> 13.042412 | D35: 24.758924 | E35: 22386 | F35: =((E35 -H35)/E35 * 100) -> 4.9316537 | G35: 19.844988 | H35: 21282 | I35: 0.26 | J35: 84.88 | K35: 21338.6
A36: kroA100-C-3-0-a | B36: 26702 | C36: =((B36 -H36)/B36 * 100) -> 9.9355853 | D36: 19.600224 | E36: 24962 | F36: =((E36 -H36)/E36 * 100) -> 3.6575595 | G36: 12.932766 | H36: 24049 | I36: 0 | J36: 67.93 | K36: 24049
A37: kroA100-C-3-1-a | B37: 25177 | C37: =((B37 -H37)/B37 * 100) -> 8.3727211 | D37: 19.394607 | E37: 24591 | F37: =((E37 -H37)/E37 * 100) -> 6.1892562 | G37: 23.13234 | H37: 23069 | I37: 1.48 | J37: 80.07 | K37: 23416.7
A38: kroA100-C-5-0-a | B38: 25179 | C38: =((B38 -H38)/B38 * 100) -> 1.7236586 | D38: 10.684815 | E38: 25367 | F38: =((E38 -H38)/E38 * 100) -> 2.4520046 | G38: 7.835761 | H38: 24745 | I38: 0 | J38: 58.51 | K38: 24745
A39: kroA100-C-5-1-a | B39: 25651 | C39: =((B39 -H39)/B39 * 100) -> 11.937156 | D39: 15.729419 | E39: 24432 | F39: =((E39 -H39)/E39 * 100) -> 7.5433857 | G39: 12.353379 | H39: 22589 | I39: 0.01 | J39: 84.44 | K39: 22591.8
A40: kroA100-C-5-3-a | B40: 24624 | C40: =((B40 -H40)/B40 * 100) -> 12.918291 | D40: 22.615217 | E40: 23859 | F40: =((E40 -H40)/E40 * 100) -> 10.126158 | G40: 22.286749 | H40: 21443 | I40: 0 | J40: 82.5 | K40: 21443
A41: kroA100-R-1-0-a | B41: 24474 | C41: =((B41 -H41)/B41 * 100) -> 13.042412 | D41: 19.840209 | E41: 22424 | F41: =((E41 -H41)/E41 * 100) -> 5.0927578 | G41: 27.446248 | H41: 21282 | I41: 0.39 | J41: 95.23 | K41: 21365.5
A42: kroA100-R-3-0-a | B42: 42058 | C42: =((B42 -H42)/B42 * 100) -> 7.713158 | D42: 10.527167 | E42: 40160 | F42: =((E42 -H42)/E42 * 100) -> 3.3515936 | G42: 21.004928 | H42: 38814 | I42: 0.16 | J42: 73.43 | K42: 38877.5
A43: kroA100-R-3-1-a | B43: 32069 | C43: =((B43 -H43)/B43 * 100) -> 8.7467648 | D43: 18.944818 | E43: 30191 | F43: =((E43 -H43)/E43 * 100) -> 3.0704515 | G43: 20.834836 | H43: 29264 | I43: 1.05 | J43: 92.64 | K43: 29578.2
A44: kroA100-R-5-0-a | B44: 52633 | C44: =((B44 -H44)/B44 * 100) -> 4.6377748 | D44: 11.07143 | E44: 52956 | F44: =((E44 -H44)/E44 * 100) -> 5.2194274 | G44: 8.6045973 | H44: 50192 | I44: 0.43 | J44: 63.04 | K44: 50411
A45: kroA100-R-5-1-a | B45: 37085 | C45: =((B45 -H45)/B45 * 100) -> 3.3382769 | D45: 14.663213 | E45: 41940 | F45: =((E45 -H45)/E45 * 100) -> 14.527897 | G45: 11.431879 | H45: 35847 | I45: 1.32 | J45: 72.97 | K45: 36328.4
A46: kroA100-R-5-3-a | B46: 28927 | C46: =((B46 -H46)/B46 * 100) -> 12.29647 | D46: 20.779215 | E46: 29558 | F46: =((E46 -H46)/E46 * 100) -> 14.168753 | G46: 18.752155 | H46: 25370 | I46: 0.87 | J46: 90.97 | K46: 25594.9
... A118: kroE100-R-5-3-a | B118: 27956 | C118: =((B118 -H118)/B118 * 100) -> 2.5039348 | D118: 19.853732 | E118: 28689 | F118: =((E118 -H118)/E118 * 100) -> 4.9949458 | G118: 18.915424 | H118: 27256 | I118: 0.22 | J118: 109.86 | K118: 27316.3
A119: swiss42-C-1-0-a | B119: 1365 | C119: =((B119 -H119)/B119 * 100) -> 6.7399267 | D119: 1.9984733 | E119: 1315 | F119: =((E119 -H119)/E119 * 100) -> 3.1939163 | G119: 1.67696 | H119: 1273 | I119: 0 | J119: 4.65
A120: swiss42-C-3-0-a | B120: 1347 | C120: =((B120 -H120)/B120 * 100) -> 0 | D120: 0.8286764 | E120: 1376 | F120: =((E120 -H120)/E120 * 100) -> 2.1075581 | G120: 1.0226472 | H120: 1347 | I120: 0 | J120: 3.56
A121: swiss42-C-3-0-b | B121: 1556 | C121: =((B121 -H121)/B121 * 100) -> 3.277635 | D121: 0.9707266 | E121: 1505 | F121: =((E121 -H121)/E121 * 100) -> 0 | G121: 1.105274 | H121: 1505 | I121: 0 | J121: 3.67
A122: swiss42-C-3-0-c | B122: 1512 | C122: =((B122 -H122)/B122 * 100) -> 2.9761905 | D122: 1.0391589 | E122: 1501 | F122: =((E122 -H122)/E122 * 100) -> 2.2651566 | G122: 0.805079 | H122: 1467 | I122: 0 | J122: 3.26
A123: swiss42-C-3-1-a | B123: 1301 | C123: =((B123 -H123)/B123 * 100) -> 0 | D123: 1.4893277 | E123: 1310 | F123: =((E123 -H123)/E123 * 100) -> 0.6870229 | G123: 1.1986269 | H123: 1301 | I123: 0.14 | J123: 4.31
A124: swiss42-C-3-1-b | B124: 1365 | C124: =((B124 -H124)/B124 * 100) -> 1.5384615 | D124: 1.3709337 | E124: 1411 | F124: =((E124 -H124)/E124 * 100) -> 4.7484054 | G124: 1.2444902 | H124: 1344 | I124: 0 | J124: 4.3
A125: swiss42-C-3-1-c | B125: 1469 | C125: =((B125 -H125)/B125 * 100) -> 7.6242342 | D125: 1.0765655 | E125: 1441 | F125: =((E125 -H125)/E125 * 100) -> 5.8292852 | G125: 1.0079625 | H125: 1357 | I125: 0 | J125: 4.26
A126: swiss42-C-5-0-a | B126: 1600 | C126: =((B126 -H126)/B126 * 100) -> 2.4375 | D126: 0.8466775 | E126: 1574 | F126: =((E126 -H126)/E126 * 100) -> 0.82592122 | G126: 0.7101158 | H126: 1561 | I126: 0 | J126: 3.01
A127: swiss42-C-5-0-b | B127: 1603 | C127: =((B127 -H127)/B127 * 100) -> 3.930131 | D127: 0.8862901 | E127: 1540 | F127: =((E127 -H127)/E127 * 100) -> 0 | G127: 0.817728 | H127: 1540 | I127: 0 | J127: 2.89
A128: swiss42-C-5-0-c | B128: 1546 | C128: =((B128 -H128)/B128 * 100) -> 0.90556274 | D128: 0.7248436 | E128: 1669 | F128: =((E128 -H128)/E128 * 100) -> 8.2085081 | G128: 0.7500512 | H128: 1532 | I128: 0 | J128: 3.03
A129: swiss42-C-5-1-a | B129: 1501 | C129: =((B129 -H129)/B129 * 100) -> 4.4636909 | D129: 1.0194186 | E129: 1479 | F129: =((E129 -H129)/E129 * 100) -> 3.0425963 | G129: 1.0467942 | H129: 1434 | I129: 0 | J129: 4.11
A130: swiss42-C-5-1-b | B130: 1536 | C130: =((B130 -H130)/B130 * 100) -> 4.3619792 | D130: 0.8642571 | E130: 1532 | F130: =((E130 -H130)/E130 * 100) -> 4.1122715 | G130: 1.1805464 | H130: 1469 | I130: 0 | J130: 4.3
...

Sheet Média das dif ILS
I6: Média das Dif (%)
H7: Instâncias | I7: Vizinho mais próximo d-relaxado com ILS | J7: Inserção d-relaxada com ILS
H8: berlin52 | I8: =AVERAGE(Resultados_ILS!C3:C34) -> 6.0926511 | J8: =AVERAGE(Resultados_ILS!F3:F34) -> 6.7837378
H9: kroA100 | I9: =AVERAGE(Resultados_ILS!C35:C46) -> 8.9753902 | J9: =AVERAGE(Resultados_ILS!F35:F46) -> 6.6942415
H10: kroA200 | I10: =AVERAGE(Resultados_ILS!C47:C58) -> 8.2059557 | J10: =AVERAGE(Resultados_ILS!F47:F58) -> 5.8409138
H11: kroB100 | I11: =AVERAGE(Resultados_ILS!C59:C70) -> 8.0403368 | J11: =AVERAGE(Resultados_ILS!F59:F70) -> 6.0179517
H12: kroB200 | I12: =AVERAGE(Resultados_ILS!C71:C82) -> 8.3557239 | J12: =AVERAGE(Resultados_ILS!F71:F82) -> 4.8020405
H13: kroC100 | I13: =AVERAGE(Resultados_ILS!C83:C94) -> 9.5033117 | J13: =AVERAGE(Resultados_ILS!F83:F94) -> 4.4216715
H14: kroD100 | I14: =AVERAGE(Resultados_ILS!C95:C106) -> 9.5357009 | J14: =AVERAGE(Resultados_ILS!F95:F106) -> 6.8969315
H15: kroE100 | I15: =AVERAGE(Resultados_ILS!C107:C118) -> 7.2206561 | J15: =AVERAGE(Resultados_ILS!F107:F118) -> 5.7605501
H16: swiss42 | I16: =AVERAGE(Resultados_ILS!C119:C150) -> 5.0932494 | J16: =AVERAGE(Resultados_ILS!F119:F150) -> 5.0078786
